<sdf version='1.7'>
  <world name='default'>
    <model name='ground_plane'>
      <static>1</static>
      <link name='link'>
        <collision name='collision'>
          <geometry>
            <plane>
              <normal>0 0 1</normal>
              <size>100 100</size>
            </plane>
          </geometry>
          <surface>
            <friction>
              <ode>
                <mu>100</mu>
                <mu2>50</mu2>
              </ode>
              <torsional>
                <ode/>
              </torsional>
            </friction>
            <contact>
              <ode/>
            </contact>
            <bounce/>
          </surface>
          <max_contacts>10</max_contacts>
        </collision>
        <visual name='visual'>
          <cast_shadows>0</cast_shadows>
          <geometry>
            <plane>
              <normal>0 0 1</normal>
              <size>100 100</size>
            </plane>
          </geometry>
          <material>
            <script>
              <uri>file://media/materials/scripts/gazebo.material</uri>
              <name>Gazebo/Grey</name>
            </script>
          </material>
        </visual>
        <self_collide>0</self_collide>
        <enable_wind>0</enable_wind>
        <kinematic>0</kinematic>
      </link>
    </model>
    <light name='sun' type='directional'>
      <cast_shadows>1</cast_shadows>
      <pose>0 0 10 0 -0 0</pose>
      <diffuse>0.8 0.8 0.8 1</diffuse>
      <specular>0.2 0.2 0.2 1</specular>
      <attenuation>
        <range>1000</range>
        <constant>0.9</constant>
        <linear>0.01</linear>
        <quadratic>0.001</quadratic>
      </attenuation>
      <direction>-0.5 0.1 -0.9</direction>
      <spot>
        <inner_angle>0</inner_angle>
        <outer_angle>0</outer_angle>
        <falloff>0</falloff>
      </spot>
    </light>
    <scene>
      <shadows>0</shadows>
      <ambient>0.4 0.4 0.4 1</ambient>
      <background>0.7 0.7 0.7 1</background>
    </scene>
    <plugin name='gazebo_ros_state' filename='libgazebo_ros_state.so'>
      <ros>
        <namespace>/ros2_grasp</namespace>
        <argument>model_states:=model_states</argument>
        <argument>link_states:=link_states</argument>
      </ros>
      <update_rate>1.0</update_rate>
    </plugin>
    <plugin name='gazebo_ros_properties' filename='libgazebo_ros_properties.so'>
      <ros>
        <namespace>/ros2_grasp</namespace>
      </ros>
    </plugin>
    <gravity>0 0 -9.8</gravity>
    <magnetic_field>6e-06 2.3e-05 -4.2e-05</magnetic_field>
    <atmosphere type='adiabatic'/>
    <physics type='ode'>
      <max_step_size>0.001</max_step_size>
      <real_time_factor>1</real_time_factor>
      <real_time_update_rate>1000</real_time_update_rate>
    </physics>
    <audio>
      <device>default</device>
    </audio>
    <wind/>
    <spherical_coordinates>
      <surface_model>EARTH_WGS84</surface_model>
      <latitude_deg>0</latitude_deg>
      <longitude_deg>0</longitude_deg>
      <elevation>0</elevation>
      <heading_deg>0</heading_deg>
    </spherical_coordinates>
    <model name='irb120'>
      <joint name='world_joint' type='fixed'>
        <pose relative_to='__model__'>0 0 0.25 0 -0 0</pose>
        <parent>world</parent>
        <child>ur_base</child>
      </joint>
      <link name='ur_base'>
        <pose relative_to='world_joint'>0 0 0 0 -0 0</pose>
        <inertial>
          <pose>-0.00246 5e-06 0.019581 0 -0 0</pose>
          <mass>106.215</mass>
          <inertia>
            <ixx>0.689983</ixx>
            <ixy>-6.10802e-05</ixy>
            <ixz>0.0836272</ixz>
            <iyy>0.724726</iyy>
            <iyz>-0.000164885</iyz>
            <izz>0.0675791</izz>
          </inertia>
        </inertial>
        <collision name='ur_base_fixed_joint_lump__collision_collision'>
          <pose>0 0 0 0 -0 0</pose>
          <geometry>
            <box>
              <size>0.35 0.35 0.5</size>
            </box>
          </geometry>
          <max_contacts>10</max_contacts>
          <surface>
            <contact>
              <ode/>
            </contact>
            <bounce/>
            <friction>
              <torsional>
                <ode/>
              </torsional>
              <ode/>
            </friction>
          </surface>
        </collision>
        <collision name='ur_base_fixed_joint_lump__base_link_collision_1'>
          <pose>0 0 0.255 0 -0 0</pose>
          <geometry>
            <mesh>
              <scale>1 1 1</scale>
              <uri>file:///home/andres/percepcion_ws/install/irb120_ros2_gazebo/share/irb120_ros2_gazebo/meshes/collision/base_link.stl</uri>
            </mesh>
          </geometry>
          <surface>
            <contact>
              <ode/>
            </contact>
            <friction>
              <ode/>
              <torsional>
                <ode/>
              </torsional>
            </friction>
            <bounce/>
          </surface>
          <max_contacts>10</max_contacts>
        </collision>
        <visual name='ur_base_fixed_joint_lump__chassis_visual_visual'>
          <pose>0 0 0 0 -0 0</pose>
          <geometry>
            <box>
              <size>0.35 0.35 0.5</size>
            </box>
          </geometry>
        </visual>
        <visual name='ur_base_fixed_joint_lump__base_link_visual_1'>
          <pose>0 0 0.255 0 -0 0</pose>
          <geometry>
            <mesh>
              <scale>1 1 1</scale>
              <uri>file:///home/andres/percepcion_ws/install/irb120_ros2_gazebo/share/irb120_ros2_gazebo/meshes/visual/base_link.dae</uri>
            </mesh>
          </geometry>
        </visual>
        <visual name='ur_base_fixed_joint_lump__camera_link_visual_2'>
          <pose>0 -0.5 1.255 3.14159 1.57079 3.14159</pose>
          <geometry>
            <box>
              <size>0.01 0.03 0.03</size>
            </box>
          </geometry>
        </visual>
        <visual name='ur_base_fixed_joint_lump__camera_link_visual_3'>
          <pose>1 -1 1.2558 3.14159 1.57079 3.14159</pose>
          <geometry>
            <cylinder>
              <length>0.1</length>
              <radius>0.002</radius>
            </cylinder>
          </geometry>
        </visual>
        <self_collide>0</self_collide>
        <sensor name='camera' type='camera'>
          <visualize>1</visualize>
          <update_rate>30</update_rate>
          <camera>
            <horizontal_fov>1.207</horizontal_fov>
            <image>
              <width>800</width>
              <height>800</height>
              <format>R8G8B8</format>
            </image>
            <clip>
              <near>0.02</near>
              <far>300</far>
            </clip>
          </camera>
          <plugin name='camera_controller' filename='libgazebo_ros_camera.so'>
            <robotNamespace/>
            <alwaysOn>1</alwaysOn>
            <updateRate>0.0</updateRate>
            <cameraName>camera</cameraName>
            <imageTopicName>camera_image_raw</imageTopicName>
            <cameraInfoTopicName>camera_info</cameraInfoTopicName>
            <frameName>camera_link_optical</frameName>
            <hackBaseline>0.07</hackBaseline>
          </plugin>
          <pose>0 -0.5 1.255 3.14159 1.57079 3.14159</pose>
        </sensor>
        <enable_wind>0</enable_wind>
        <kinematic>0</kinematic>
      </link>
      <joint name='joint_1' type='revolute'>
        <pose relative_to='ur_base'>0 0 0.255 0 -0 0</pose>
        <parent>ur_base</parent>
        <child>link_1</child>
        <axis>
          <xyz>0 0 1</xyz>
          <limit>
            <lower>-2.87979</lower>
            <upper>2.87979</upper>
            <effort>0</effort>
            <velocity>4.36332</velocity>
          </limit>
          <dynamics>
            <damping>50</damping>
            <friction>1</friction>
            <spring_reference>0</spring_reference>
            <spring_stiffness>0</spring_stiffness>
          </dynamics>
        </axis>
      </joint>
      <link name='link_1'>
        <pose relative_to='joint_1'>0 0 0 0 -0 0</pose>
        <inertial>
          <pose>9.8e-05 -0.00012 0.23841 0 -0 0</pose>
          <mass>3.067</mass>
          <inertia>
            <ixx>0.0142175</ixx>
            <ixy>-1.28579e-05</ixy>
            <ixz>-2.31364e-05</ixz>
            <iyy>0.0144041</iyy>
            <iyz>1.93404e-05</iyz>
            <izz>0.0104533</izz>
          </inertia>
        </inertial>
        <collision name='link_1_collision'>
          <pose>0 0 0 0 -0 0</pose>
          <geometry>
            <mesh>
              <scale>1 1 1</scale>
              <uri>file:///home/andres/percepcion_ws/install/irb120_ros2_gazebo/share/irb120_ros2_gazebo/meshes/collision/link_1.stl</uri>
            </mesh>
          </geometry>
          <surface>
            <contact>
              <ode/>
            </contact>
            <friction>
              <ode/>
              <torsional>
                <ode/>
              </torsional>
            </friction>
            <bounce/>
          </surface>
          <max_contacts>10</max_contacts>
        </collision>
        <visual name='link_1_visual'>
          <pose>0 0 0 0 -0 0</pose>
          <geometry>
            <mesh>
              <scale>1 1 1</scale>
              <uri>file:///home/andres/percepcion_ws/install/irb120_ros2_gazebo/share/irb120_ros2_gazebo/meshes/visual/link_1.dae</uri>
            </mesh>
          </geometry>
        </visual>
        <self_collide>0</self_collide>
        <enable_wind>0</enable_wind>
        <kinematic>0</kinematic>
      </link>
      <joint name='joint_2' type='revolute'>
        <pose relative_to='link_1'>0 0 0.29 0 -0 0</pose>
        <parent>link_1</parent>
        <child>link_2</child>
        <axis>
          <xyz>0 1 0</xyz>
          <limit>
            <lower>-1.91986</lower>
            <upper>1.91986</upper>
            <effort>0</effort>
            <velocity>4.36332</velocity>
          </limit>
          <dynamics>
            <damping>50</damping>
            <friction>1</friction>
            <spring_reference>0</spring_reference>
            <spring_stiffness>0</spring_stiffness>
          </dynamics>
        </axis>
      </joint>
      <link name='link_2'>
        <pose relative_to='joint_2'>0 0 0 0 -0 0</pose>
        <inertial>
          <pose>0.00078 -0.00212 0.10124 0 -0 0</pose>
          <mass>3.909</mass>
          <inertia>
            <ixx>0.0603111</ixx>
            <ixy>9.83431e-06</ixy>
            <ixz>5.72407e-05</ixz>
            <iyy>0.041569</iyy>
            <iyz>-0.00050497</iyz>
            <izz>0.0259548</izz>
          </inertia>
        </inertial>
        <collision name='link_2_collision'>
          <pose>0 0 0 0 -0 0</pose>
          <geometry>
            <mesh>
              <scale>1 1 1</scale>
              <uri>file:///home/andres/percepcion_ws/install/irb120_ros2_gazebo/share/irb120_ros2_gazebo/meshes/collision/link_2.stl</uri>
            </mesh>
          </geometry>
          <surface>
            <contact>
              <ode/>
            </contact>
            <friction>
              <ode/>
              <torsional>
                <ode/>
              </torsional>
            </friction>
            <bounce/>
          </surface>
          <max_contacts>10</max_contacts>
        </collision>
        <visual name='link_2_visual'>
          <pose>0 0 0 0 -0 0</pose>
          <geometry>
            <mesh>
              <scale>1 1 1</scale>
              <uri>file:///home/andres/percepcion_ws/install/irb120_ros2_gazebo/share/irb120_ros2_gazebo/meshes/visual/link_2.dae</uri>
            </mesh>
          </geometry>
        </visual>
        <self_collide>0</self_collide>
        <enable_wind>0</enable_wind>
        <kinematic>0</kinematic>
      </link>
      <joint name='joint_3' type='revolute'>
        <pose relative_to='link_2'>0 0 0.27 0 -0 0</pose>
        <parent>link_2</parent>
        <child>link_3</child>
        <axis>
          <xyz>0 1 0</xyz>
          <limit>
            <lower>-1.91986</lower>
            <upper>1.22173</upper>
            <effort>0</effort>
            <velocity>4.36332</velocity>
          </limit>
          <dynamics>
            <damping>10</damping>
            <friction>1</friction>
            <spring_reference>0</spring_reference>
            <spring_stiffness>0</spring_stiffness>
          </dynamics>
        </axis>
      </joint>
      <link name='link_3'>
        <pose relative_to='joint_3'>0 0 0 0 -0 0</pose>
        <inertial>
          <pose>0.02281 0.00106 0.05791 0 -0 0</pose>
          <mass>2.944</mass>
          <inertia>
            <ixx>0.00835606</ixx>
            <ixy>-8.01545e-05</ixy>
            <ixz>0.00142884</ixz>
            <iyy>0.016713</iyy>
            <iyz>-0.000182227</iyz>
            <izz>0.0126984</izz>
          </inertia>
        </inertial>
        <collision name='link_3_collision'>
          <pose>0 0 0 0 -0 0</pose>
          <geometry>
            <mesh>
              <scale>1 1 1</scale>
              <uri>file:///home/andres/percepcion_ws/install/irb120_ros2_gazebo/share/irb120_ros2_gazebo/meshes/collision/link_3.stl</uri>
            </mesh>
          </geometry>
          <surface>
            <contact>
              <ode/>
            </contact>
            <friction>
              <ode/>
              <torsional>
                <ode/>
              </torsional>
            </friction>
            <bounce/>
          </surface>
          <max_contacts>10</max_contacts>
        </collision>
        <visual name='link_3_visual'>
          <pose>0 0 0 0 -0 0</pose>
          <geometry>
            <mesh>
              <scale>1 1 1</scale>
              <uri>file:///home/andres/percepcion_ws/install/irb120_ros2_gazebo/share/irb120_ros2_gazebo/meshes/visual/link_3.dae</uri>
            </mesh>
          </geometry>
        </visual>
        <self_collide>0</self_collide>
        <enable_wind>0</enable_wind>
        <kinematic>0</kinematic>
      </link>
      <joint name='joint_4' type='revolute'>
        <pose relative_to='link_3'>0 0 0.07 0 -0 0</pose>
        <parent>link_3</parent>
        <child>link_4</child>
        <axis>
          <xyz>1 0 0</xyz>
          <limit>
            <lower>-2.79253</lower>
            <upper>2.79253</upper>
            <effort>0</effort>
            <velocity>5.58505</velocity>
          </limit>
          <dynamics>
            <damping>5</damping>
            <friction>1</friction>
            <spring_reference>0</spring_reference>
            <spring_stiffness>0</spring_stiffness>
          </dynamics>
        </axis>
      </joint>
      <link name='link_4'>
        <pose relative_to='joint_4'>0 0 0 0 -0 0</pose>
        <inertial>
          <pose>0.2247 0.00015 0.00041 0 -0 0</pose>
          <mass>1.328</mass>
          <inertia>
            <ixx>0.00284661</ixx>
            <ixy>-2.12765e-05</ixy>
            <ixz>-1.6435e-05</ixz>
            <iyy>0.00401346</iyy>
            <iyz>1.31336e-05</iyz>
            <izz>0.0052535</izz>
          </inertia>
        </inertial>
        <collision name='link_4_collision'>
          <pose>0 0 0 0 -0 0</pose>
          <geometry>
            <mesh>
              <scale>1 1 1</scale>
              <uri>file:///home/andres/percepcion_ws/install/irb120_ros2_gazebo/share/irb120_ros2_gazebo/meshes/collision/link_4.stl</uri>
            </mesh>
          </geometry>
          <surface>
            <contact>
              <ode/>
            </contact>
            <friction>
              <ode/>
              <torsional>
                <ode/>
              </torsional>
            </friction>
            <bounce/>
          </surface>
          <max_contacts>10</max_contacts>
        </collision>
        <visual name='link_4_visual'>
          <pose>0 0 0 0 -0 0</pose>
          <geometry>
            <mesh>
              <scale>1 1 1</scale>
              <uri>file:///home/andres/percepcion_ws/install/irb120_ros2_gazebo/share/irb120_ros2_gazebo/meshes/visual/link_4.dae</uri>
            </mesh>
          </geometry>
        </visual>
        <self_collide>0</self_collide>
        <enable_wind>0</enable_wind>
        <kinematic>0</kinematic>
      </link>
      <joint name='joint_5' type='revolute'>
        <pose relative_to='link_4'>0.302 0 0 0 -0 0</pose>
        <parent>link_4</parent>
        <child>link_5</child>
        <axis>
          <xyz>0 1 0</xyz>
          <limit>
            <lower>-2.0944</lower>
            <upper>2.0944</upper>
            <effort>0</effort>
            <velocity>5.58505</velocity>
          </limit>
          <dynamics>
            <damping>2</damping>
            <friction>1</friction>
            <spring_reference>0</spring_reference>
            <spring_stiffness>0</spring_stiffness>
          </dynamics>
        </axis>
      </joint>
      <link name='link_5'>
        <pose relative_to='joint_5'>0 0 0 0 -0 0</pose>
        <inertial>
          <pose>-0.00109 3.7e-05 6.2e-05 0 -0 0</pose>
          <mass>0.546</mass>
          <inertia>
            <ixx>0.000404891</ixx>
            <ixy>1.61943e-06</ixy>
            <ixz>8.46805e-07</ixz>
            <iyy>0.000892825</iyy>
            <iyz>-1.51792e-08</iyz>
            <izz>0.000815468</izz>
          </inertia>
        </inertial>
        <collision name='link_5_collision'>
          <pose>0 0 0 0 -0 0</pose>
          <geometry>
            <mesh>
              <scale>1 1 1</scale>
              <uri>file:///home/andres/percepcion_ws/install/irb120_ros2_gazebo/share/irb120_ros2_gazebo/meshes/collision/link_5.stl</uri>
            </mesh>
          </geometry>
          <surface>
            <contact>
              <ode/>
            </contact>
            <friction>
              <ode/>
              <torsional>
                <ode/>
              </torsional>
            </friction>
            <bounce/>
          </surface>
          <max_contacts>10</max_contacts>
        </collision>
        <visual name='link_5_visual'>
          <pose>0 0 0 0 -0 0</pose>
          <geometry>
            <mesh>
              <scale>1 1 1</scale>
              <uri>file:///home/andres/percepcion_ws/install/irb120_ros2_gazebo/share/irb120_ros2_gazebo/meshes/visual/link_5.dae</uri>
            </mesh>
          </geometry>
        </visual>
        <self_collide>0</self_collide>
        <enable_wind>0</enable_wind>
        <kinematic>0</kinematic>
      </link>
      <joint name='joint_6' type='revolute'>
        <pose relative_to='link_5'>0.072 0 0 0 -0 0</pose>
        <parent>link_5</parent>
        <child>link_6</child>
        <axis>
          <xyz>1 0 0</xyz>
          <limit>
            <lower>-6.98132</lower>
            <upper>6.98132</upper>
            <effort>0</effort>
            <velocity>7.33038</velocity>
          </limit>
          <dynamics>
            <damping>1</damping>
            <friction>1</friction>
            <spring_reference>0</spring_reference>
            <spring_stiffness>0</spring_stiffness>
          </dynamics>
        </axis>
      </joint>
      <link name='link_6'>
        <pose relative_to='joint_6'>0 0 0 0 -0 0</pose>
        <inertial>
          <pose>-0.006006 -0.000507 0.001239 0 -0 0</pose>
          <mass>0.143</mass>
          <inertia>
            <ixx>0.00300653</ixx>
            <ixy>1.32865e-06</ixy>
            <ixz>-4.87384e-06</ixz>
            <iyy>0.00301005</iyy>
            <iyz>1.65725e-06</iyz>
            <izz>0.00300443</izz>
          </inertia>
        </inertial>
        <collision name='link_6_collision'>
          <pose>0 0 0 0 -0 0</pose>
          <geometry>
            <mesh>
              <scale>1 1 1</scale>
              <uri>file:///home/andres/percepcion_ws/install/irb120_ros2_gazebo/share/irb120_ros2_gazebo/meshes/collision/link_6.stl</uri>
            </mesh>
          </geometry>
          <surface>
            <contact>
              <ode/>
            </contact>
            <friction>
              <ode/>
              <torsional>
                <ode/>
              </torsional>
            </friction>
            <bounce/>
          </surface>
          <max_contacts>10</max_contacts>
        </collision>
        <collision name='link_6_fixed_joint_lump__schunk_coupler_collision_1'>
          <pose>0.001 0 0 1.5708 0.785398 1.5708</pose>
          <geometry>
            <mesh>
              <scale>1 1 1</scale>
              <uri>file:///home/andres/percepcion_ws/install/irb120_ros2_gazebo/share/irb120_ros2_gazebo/meshes/egp64/egp64_Adapter.dae</uri>
            </mesh>
          </geometry>
          <surface>
            <contact>
              <ode/>
            </contact>
            <friction>
              <ode>
                <mu>0.9</mu>
                <mu2>0.9</mu2>
              </ode>
              <torsional>
                <ode/>
              </torsional>
            </friction>
            <bounce/>
          </surface>
          <max_contacts>10</max_contacts>
        </collision>
        <collision name='link_6_fixed_joint_lump__egp64_gripper_base_link_collision_2'>
          <pose>0.02147 -0.00985 0.035476 1.5708 0.785398 1.5708</pose>
          <geometry>
            <mesh>
              <scale>1 1 1</scale>
              <uri>file:///home/andres/percepcion_ws/install/irb120_ros2_gazebo/share/irb120_ros2_gazebo/meshes/egp64/egp64_BaseNoAdapter.dae</uri>
            </mesh>
          </geometry>
          <surface>
            <contact>
              <ode/>
            </contact>
            <friction>
              <ode/>
              <torsional>
                <ode/>
              </torsional>
            </friction>
            <bounce/>
          </surface>
          <max_contacts>10</max_contacts>
        </collision>
        <visual name='link_6_visual'>
          <pose>0 0 0 0 -0 0</pose>
          <geometry>
            <mesh>
              <scale>1 1 1</scale>
              <uri>file:///home/andres/percepcion_ws/install/irb120_ros2_gazebo/share/irb120_ros2_gazebo/meshes/visual/link_6.dae</uri>
            </mesh>
          </geometry>
        </visual>
        <visual name='link_6_fixed_joint_lump__schunk_coupler_visual_1'>
          <pose>0.001 0 0 1.5708 0.785398 1.5708</pose>
          <geometry>
            <mesh>
              <scale>1 1 1</scale>
              <uri>file:///home/andres/percepcion_ws/install/irb120_ros2_gazebo/share/irb120_ros2_gazebo/meshes/egp64/egp64_Adapter.dae</uri>
            </mesh>
          </geometry>
          <material>
            <script>
              <name>Gazebo/Black</name>
              <uri>file://media/materials/scripts/gazebo.material</uri>
            </script>
          </material>
        </visual>
        <visual name='link_6_fixed_joint_lump__egp64_gripper_base_link_visual_2'>
          <pose>0.02147 -0.00985 0.035476 1.5708 0.785398 1.5708</pose>
          <geometry>
            <mesh>
              <scale>1 1 1</scale>
              <uri>file:///home/andres/percepcion_ws/install/irb120_ros2_gazebo/share/irb120_ros2_gazebo/meshes/egp64/egp64_BaseNoAdapter.dae</uri>
            </mesh>
          </geometry>
        </visual>
        <self_collide>0</self_collide>
        <enable_wind>0</enable_wind>
        <kinematic>0</kinematic>
      </link>
      <joint name='EE_egp64_joint' type='prismatic'>
        <pose relative_to='link_6'>0.17147 0.000757 -0.000587 1.5708 0.785398 1.5708</pose>
        <parent>link_6</parent>
        <child>EE_egp64</child>
        <axis>
          <xyz>1 0 0</xyz>
          <limit>
            <lower>0</lower>
            <upper>0</upper>
            <effort>10000</effort>
            <velocity>0</velocity>
          </limit>
          <dynamics>
            <damping>1</damping>
            <friction>1</friction>
            <spring_reference>0</spring_reference>
            <spring_stiffness>0</spring_stiffness>
          </dynamics>
        </axis>
      </joint>
      <link name='EE_egp64'>
        <pose relative_to='EE_egp64_joint'>0 0 0 0 -0 0</pose>
        <inertial>
          <pose>0 0 0 0 -0 0</pose>
          <mass>1e-05</mass>
          <inertia>
            <ixx>0.001</ixx>
            <ixy>0</ixy>
            <ixz>0</ixz>
            <iyy>0.001</iyy>
            <iyz>0</iyz>
            <izz>0.001</izz>
          </inertia>
        </inertial>
        <visual name='EE_egp64_visual'>
          <pose>0 0 0 0 -0 0</pose>
          <geometry>
            <box>
              <size>0.001 0.001 0.001</size>
            </box>
          </geometry>
        </visual>
        <self_collide>0</self_collide>
        <enable_wind>0</enable_wind>
        <kinematic>0</kinematic>
      </link>
      <joint name='egp64_finger_left_joint' type='prismatic'>
        <pose relative_to='link_6'>0.02147 -0.004893 0.01946 1.5708 0.785398 1.5708</pose>
        <parent>link_6</parent>
        <child>egp64_finger_left_link</child>
        <axis>
          <xyz>-1 0 0</xyz>
          <limit>
            <lower>-0.001</lower>
            <upper>0.04</upper>
            <effort>100</effort>
            <velocity>0.2</velocity>
          </limit>
          <dynamics>
            <damping>1</damping>
            <friction>1</friction>
            <spring_reference>0</spring_reference>
            <spring_stiffness>0</spring_stiffness>
          </dynamics>
        </axis>
      </joint>
      <link name='egp64_finger_left_link'>
        <pose relative_to='egp64_finger_left_joint'>0 0 0 0 -0 0</pose>
        <inertial>
          <pose>0.03568 -0.005547 0.00062 0 -0 0</pose>
          <mass>0.003</mass>
          <inertia>
            <ixx>0.00200003</ixx>
            <ixy>-2.84394e-07</ixy>
            <ixz>-7.7562e-08</ixz>
            <iyy>0.00200261</iyy>
            <iyz>-8.4568e-09</iyz>
            <izz>0.00200264</izz>
          </inertia>
        </inertial>
        <collision name='egp64_finger_left_link_collision'>
          <pose>0 0 0 0 -0 0</pose>
          <geometry>
            <mesh>
              <scale>1 1 1</scale>
              <uri>file:///home/andres/percepcion_ws/install/irb120_ros2_gazebo/share/irb120_ros2_gazebo/meshes/egp64/egp64_LeftFingerBase.dae</uri>
            </mesh>
          </geometry>
          <surface>
            <contact>
              <ode/>
            </contact>
            <friction>
              <ode/>
              <torsional>
                <ode/>
              </torsional>
            </friction>
            <bounce/>
          </surface>
          <max_contacts>10</max_contacts>
        </collision>
        <collision name='egp64_finger_left_link_fixed_joint_lump__egp64_fingertip_left_link_collision_1'>
          <pose>0.03869 -0.0005 0.00093 0 -0 0</pose>
          <geometry>
            <mesh>
              <scale>1 1 1</scale>
              <uri>file:///home/andres/percepcion_ws/install/irb120_ros2_gazebo/share/irb120_ros2_gazebo/meshes/egp64/egp64_LeftFinger.dae</uri>
            </mesh>
          </geometry>
          <surface>
            <contact>
              <ode/>
            </contact>
            <friction>
              <ode/>
              <torsional>
                <ode/>
              </torsional>
            </friction>
            <bounce/>
          </surface>
          <max_contacts>10</max_contacts>
        </collision>
        <visual name='egp64_finger_left_link_visual'>
          <pose>0 0 0 0 -0 0</pose>
          <geometry>
            <mesh>
              <scale>1 1 1</scale>
              <uri>file:///home/andres/percepcion_ws/install/irb120_ros2_gazebo/share/irb120_ros2_gazebo/meshes/egp64/egp64_LeftFingerBase.dae</uri>
            </mesh>
          </geometry>
        </visual>
        <visual name='egp64_finger_left_link_fixed_joint_lump__egp64_fingertip_left_link_visual_1'>
          <pose>0.03869 -0.0005 0.00093 0 -0 0</pose>
          <geometry>
            <mesh>
              <scale>1 1 1</scale>
              <uri>file:///home/andres/percepcion_ws/install/irb120_ros2_gazebo/share/irb120_ros2_gazebo/meshes/egp64/egp64_LeftFinger.dae</uri>
            </mesh>
          </geometry>
        </visual>
        <self_collide>0</self_collide>
        <enable_wind>0</enable_wind>
        <kinematic>0</kinematic>
      </link>
      <joint name='egp64_finger_right_joint' type='prismatic'>
        <pose relative_to='link_6'>0.02147 -0.024926 0.042037 1.5708 0.785398 1.5708</pose>
        <parent>link_6</parent>
        <child>egp64_finger_right_link</child>
        <axis>
          <xyz>1 0 0</xyz>
          <limit>
            <lower>-0.001</lower>
            <upper>0.04</upper>
            <effort>100</effort>
            <velocity>0.2</velocity>
          </limit>
          <dynamics>
            <damping>1</damping>
            <friction>1</friction>
            <spring_reference>0</spring_reference>
            <spring_stiffness>0</spring_stiffness>
          </dynamics>
        </axis>
      </joint>
      <link name='egp64_finger_right_link'>
        <pose relative_to='egp64_finger_right_joint'>0 0 0 0 -0 0</pose>
        <inertial>
          <pose>-0.018273 -0.005327 0.00062 0 -0 0</pose>
          <mass>0.003</mass>
          <inertia>
            <ixx>0.00200001</ixx>
            <ixy>1.23691e-08</ixy>
            <ixz>1.10608e-08</ixz>
            <iyy>0.00200006</iyy>
            <iyz>-2.5792e-09</iyz>
            <izz>0.00200006</izz>
          </inertia>
        </inertial>
        <collision name='egp64_finger_right_link_collision'>
          <pose>0 0 0 0 -0 0</pose>
          <geometry>
            <mesh>
              <scale>1 1 1</scale>
              <uri>file:///home/andres/percepcion_ws/install/irb120_ros2_gazebo/share/irb120_ros2_gazebo/meshes/egp64/egp64_RightFingerBase.dae</uri>
            </mesh>
          </geometry>
          <surface>
            <contact>
              <ode/>
            </contact>
            <friction>
              <ode/>
              <torsional>
                <ode/>
              </torsional>
            </friction>
            <bounce/>
          </surface>
          <max_contacts>10</max_contacts>
        </collision>
        <collision name='egp64_finger_right_link_fixed_joint_lump__egp64_fingertip_right_link_collision_1'>
          <pose>-0.01211 -0.00197 0.00093 0 -0 0</pose>
          <geometry>
            <mesh>
              <scale>1 1 1</scale>
              <uri>file:///home/andres/percepcion_ws/install/irb120_ros2_gazebo/share/irb120_ros2_gazebo/meshes/egp64/egp64_RightFinger.dae</uri>
            </mesh>
          </geometry>
          <surface>
            <contact>
              <ode/>
            </contact>
            <friction>
              <ode/>
              <torsional>
                <ode/>
              </torsional>
            </friction>
            <bounce/>
          </surface>
          <max_contacts>10</max_contacts>
        </collision>
        <visual name='egp64_finger_right_link_visual'>
          <pose>0 0 0 0 -0 0</pose>
          <geometry>
            <mesh>
              <scale>1 1 1</scale>
              <uri>file:///home/andres/percepcion_ws/install/irb120_ros2_gazebo/share/irb120_ros2_gazebo/meshes/egp64/egp64_RightFingerBase.dae</uri>
            </mesh>
          </geometry>
        </visual>
        <visual name='egp64_finger_right_link_fixed_joint_lump__egp64_fingertip_right_link_visual_1'>
          <pose>-0.01211 -0.00197 0.00093 0 -0 0</pose>
          <geometry>
            <mesh>
              <scale>1 1 1</scale>
              <uri>file:///home/andres/percepcion_ws/install/irb120_ros2_gazebo/share/irb120_ros2_gazebo/meshes/egp64/egp64_RightFinger.dae</uri>
            </mesh>
          </geometry>
        </visual>
        <self_collide>0</self_collide>
        <enable_wind>0</enable_wind>
        <kinematic>0</kinematic>
      </link>
      <static>0</static>
      <plugin name='gazebo_ros2_control' filename='libgazebo_ros2_control.so'>
        <robot_sim_type>gazebo_ros2_control/GazeboSystem</robot_sim_type>
        <parameters>/home/andres/percepcion_ws/install/irb120_ros2_gazebo/share/irb120_ros2_gazebo/config/irb120egp64_controller.yaml</parameters>
      </plugin>
      <pose>0 0 0 0 -0 0</pose>
    </model>
    <model name='conveyor_belt'>
      <model name='conveyorbelt_fixed'>
        <static>1</static>
        <link name='belt_visual'>
          <visual name='visual'>
            <geometry>
              <mesh>
                <scale>1 1 1</scale>
                <uri>model://conveyor_belt/meshes/conveyor_belt.dae</uri>
              </mesh>
            </geometry>
          </visual>
          <collision name='collision'>
            <geometry>
              <mesh>
                <scale>1 1 1</scale>
                <uri>model://conveyor_belt/meshes/conveyor_belt.dae</uri>
              </mesh>
            </geometry>
            <max_contacts>10</max_contacts>
            <surface>
              <contact>
                <ode/>
              </contact>
              <bounce/>
              <friction>
                <torsional>
                  <ode/>
                </torsional>
                <ode/>
              </friction>
            </surface>
            <origin xyz='0.0 0.0 0' rpy='0.0 0.0 0.0'/>
          </collision>
          <self_collide>0</self_collide>
          <enable_wind>0</enable_wind>
          <kinematic>0</kinematic>
        </link>
      </model>
      <model name='conveyorbelt_moving'>
        <allow_auto_disable>0</allow_auto_disable>
        <static>0</static>
        <pose>0 0 0.741 0 -0 0</pose>
        <link name='belt_moving'>
          <inertial>
            <mass>100</mass>
            <inertia>
              <ixx>0</ixx>
              <ixy>0</ixy>
              <ixz>0</ixz>
              <iyy>0</iyy>
              <iyz>0</iyz>
              <izz>0</izz>
            </inertia>
            <pose>0 0 0 0 -0 0</pose>
          </inertial>
          <collision name='belt_collision'>
            <geometry>
              <box>
                <size>0.425 1.2 1e-05</size>
              </box>
            </geometry>
            <surface>
              <friction>
                <ode>
                  <mu>100</mu>
                  <mu2>100</mu2>
                </ode>
                <torsional>
                  <coefficient>1000</coefficient>
                  <patch_radius>0.1</patch_radius>
                  <ode/>
                </torsional>
              </friction>
              <contact>
                <ode/>
              </contact>
              <bounce/>
            </surface>
            <max_contacts>10</max_contacts>
          </collision>
          <self_collide>0</self_collide>
          <enable_wind>0</enable_wind>
          <kinematic>0</kinematic>
        </link>
      </model>
      <joint name='belt_joint' type='prismatic'>
        <parent>conveyorbelt_fixed::belt_visual</parent>
        <child>conveyorbelt_moving::belt_moving</child>
        <axis>
          <xyz expressed_in='__model__'>0 1 0</xyz>
          <limit>
            <lower>0</lower>
            <upper>0.01</upper>
          </limit>
          <dynamics>
            <spring_reference>0</spring_reference>
            <spring_stiffness>0</spring_stiffness>
          </dynamics>
        </axis>
      </joint>
      <plugin name='ros2_conveyorbelt_plugin' filename='libros2_conveyorbelt_plugin.so'>
        <ros>
          <namespace/>
        </ros>
        <max_velocity>1.0</max_velocity>
        <publish_rate>1000</publish_rate>
      </plugin>
      <pose>-0.010782 -0.807753 0 0 -0 0</pose>
    </model>
    <state world_name='default'>
      <sim_time>581 538000000</sim_time>
      <real_time>208 815575439</real_time>
      <wall_time>1716871599 307494283</wall_time>
      <iterations>208264</iterations>
      <model name='box2'>
        <pose>0.540917 0.011581 -0 0 -0 0</pose>
        <scale>1 1 1</scale>
        <link name='caja_link'>
          <pose>0.540917 0.011581 -0 0 -0 0</pose>
          <velocity>0 0 0 0 -0 0</velocity>
          <acceleration>0 1e-06 17.1133 1.83083 -0.625148 -1.5e-05</acceleration>
          <wrench>0 2e-06 54.3518 0 -0 0</wrench>
        </link>
      </model>
      <model name='box3'>
        <pose>0.240979 0.479223 -0 0 -0 0</pose>
        <scale>1 1 1</scale>
        <link name='caja_link'>
          <pose>0.240979 0.479223 -0 0 -0 0</pose>
          <velocity>0 0 0 0 -0 0</velocity>
          <acceleration>0 1e-06 17.4182 2.25283 0.950041 -1.6e-05</acceleration>
          <wrench>0 2e-06 55.3203 0 -0 0</wrench>
        </link>
      </model>
      <model name='box4'>
        <pose>-0.331145 0.456863 -0 0 -0 0</pose>
        <scale>1 1 1</scale>
        <link name='caja_link'>
          <pose>-0.331145 0.456863 -0 0 -0 0</pose>
          <velocity>0 0 0 0 -0 0</velocity>
          <acceleration>0 1e-06 17.4182 2.25282 0.95004 -1.6e-05</acceleration>
          <wrench>0 2e-06 55.3203 0 -0 0</wrench>
        </link>
      </model>
      <model name='box5'>
        <pose>-0.480689 -0.009189 -1e-05 8e-06 -7e-06 -0</pose>
        <scale>1 1 1</scale>
        <link name='caja_link'>
          <pose>-0.480689 -0.009189 -1e-05 8e-06 -7e-06 -0</pose>
          <velocity>0 0 0 0 -0 0</velocity>
          <acceleration>0 0 -9.8 0 -0 8e-06</acceleration>
          <wrench>0 0 -31.1248 0 -0 0</wrench>
        </link>
      </model>
      <model name='conveyor_belt'>
        <pose>-0.010782 -0.807753 0 0 -0 0</pose>
        <scale>1 1 1</scale>
        <model name='conveyorbelt_fixed'>
          <pose>-0.010782 -0.807753 0 0 -0 0</pose>
          <scale>1 1 1</scale>
          <link name='belt_visual'>
            <pose>-0.010782 -0.807753 0 0 -0 0</pose>
            <velocity>0 0 0 0 -0 0</velocity>
            <acceleration>0 0 0 0 -0 0</acceleration>
            <wrench>0 0 0 0 -0 0</wrench>
          </link>
        </model>
        <model name='conveyorbelt_moving'>
          <pose>-0.010782 -0.807753 0.741 0 -0 0</pose>
          <scale>1 1 1</scale>
          <link name='belt_moving'>
            <pose>-0.010782 -0.801153 0.741 0 -0 0</pose>
            <velocity>-0 0 0 0 -0 0</velocity>
            <acceleration>-0 0 0 0 -0 0</acceleration>
            <wrench>-0 0 0 0 -0 0</wrench>
          </link>
        </model>
      </model>
      <model name='ground_plane'>
        <pose>0 0 0 0 -0 0</pose>
        <scale>1 1 1</scale>
        <link name='link'>
          <pose>0 0 0 0 -0 0</pose>
          <velocity>0 0 0 0 -0 0</velocity>
          <acceleration>0 0 0 0 -0 0</acceleration>
          <wrench>0 0 0 0 -0 0</wrench>
        </link>
      </model>
      <model name='irb120'>
        <pose>-0 0 0 0 -0 0</pose>
        <scale>1 1 1</scale>
        <link name='EE_egp64'>
          <pose>0.546546 0.000755 1.12433 1.59693 0.785223 1.58927</pose>
          <velocity>0.001416 -2.1e-05 -0.014451 1.9e-05 0.026458 -1.7e-05</velocity>
          <acceleration>1.41901 -0.017818 -14.4525 0.012943 -0.029033 -0.021428</acceleration>
          <wrench>1.4e-05 -0 -0.000145 0 -0 0</wrench>
        </link>
        <link name='egp64_finger_left_link'>
          <pose>0.396942 -0.004892 1.14715 1.59693 0.785223 1.58927</pose>
          <velocity>0.00202 -1.7e-05 -0.010494 1.9e-05 0.026458 -1.7e-05</velocity>
          <acceleration>1.25132 -0.013695 -10.4976 0.012887 -0.02905 -0.021368</acceleration>
          <wrench>0.003754 -4.1e-05 -0.031493 0 -0 0</wrench>
        </link>
        <link name='egp64_finger_right_link'>
          <pose>0.397359 -0.024925 1.16972 1.59693 0.785223 1.58927</pose>
          <velocity>0.002617 -1.8e-05 -0.010506 1.9e-05 0.026458 -1.7e-05</velocity>
          <acceleration>2.8609 -0.014925 -10.5283 0.012829 -0.029048 -0.021287</acceleration>
          <wrench>0.008583 -4.5e-05 -0.031585 0 -0 0</wrench>
        </link>
        <link name='link_1'>
          <pose>-2e-06 -0 0.505 0 2e-06 -3e-06</pose>
          <velocity>0 -4e-06 -0 9e-06 7e-06 -1.5e-05</velocity>
          <acceleration>0.003526 -0.005143 -0.00047 0.005969 0.009639 -0.014163</acceleration>
          <wrench>0.010815 -0.015773 -0.001442 0 -0 0</wrench>
        </link>
        <link name='link_2'>
          <pose>-1e-06 -0 0.795 0 -0.000407 -3e-06</pose>
          <velocity>2e-06 -7e-06 -0 1.2e-05 -0.000567 -1.6e-05</velocity>
          <acceleration>-0.053197 -0.006618 -8.2e-05 0.009672 -0.563971 -0.015035</acceleration>
          <wrench>-0.207949 -0.025871 -0.000321 0 -0 0</wrench>
        </link>
        <link name='link_3'>
          <pose>-0.000111 -0 1.065 0 0.018446 -3e-06</pose>
          <velocity>-0.000151 -1.1e-05 -0 1.3e-05 0.026415 -1.6e-05</velocity>
          <acceleration>1.37016 -0.009332 -0.631238 0.021267 1.28589 -0.019853</acceleration>
          <wrench>4.03376 -0.027474 -1.85836 0 -0 0</wrench>
        </link>
        <link name='link_4'>
          <pose>0.00118 -0 1.13499 0 0.018446 -3e-06</pose>
          <velocity>0.001698 -1.2e-05 -3.5e-05 1.4e-05 0.026415 -1.6e-05</velocity>
          <acceleration>1.60199 -0.012708 -5.97025 0.009574 1.28576 -0.017452</acceleration>
          <wrench>2.12745 -0.016877 -7.92849 0 -0 0</wrench>
        </link>
        <link name='link_5'>
          <pose>0.303128 -1e-06 1.12942 -0 0.01848 -3e-06</pose>
          <velocity>0.001551 -1.7e-05 -0.008011 1.4e-05 0.026458 -1.7e-05</velocity>
          <acceleration>1.55568 -0.013881 -7.98306 0.011663 1.3284 -0.014725</acceleration>
          <wrench>0.849401 -0.007579 -4.35875 0 -0 0</wrench>
        </link>
        <link name='link_6'>
          <pose>0.375116 -1e-06 1.12809 4e-06 0.01848 -3e-06</pose>
          <velocity>0.001516 -1.8e-05 -0.009915 1.9e-05 0.026458 -1.7e-05</velocity>
          <acceleration>1.55402 -0.014952 -9.75847 0.015477 1.3285 -0.015437</acceleration>
          <wrench>0.222224 -0.002138 -1.39546 0 -0 0</wrench>
        </link>
        <link name='ur_base'>
          <pose>-0 0 0.25 0 -0 0</pose>
          <velocity>0 0 -0 8e-06 3e-06 -7e-06</velocity>
          <acceleration>0.000139 3.3e-05 -0.000447 0.004801 0.006242 -0.006436</acceleration>
          <wrench>0.014737 0.00346 -0.047469 0 -0 0</wrench>
        </link>
      </model>
      <light name='sun'>
        <pose>0 0 10 0 -0 0</pose>
      </light>
    </state>
    <gui fullscreen='0'>
      <camera name='user_camera'>
        <pose>-2.12365 -0.536654 2.91898 0 0.837802 0.188182</pose>
        <view_controller>orbit</view_controller>
        <projection_type>perspective</projection_type>
      </camera>
    </gui>
    <model name='box2'>
      <link name='caja_link'>
        <inertial>
          <pose>0 0.10733 -0 0 -0 0</pose>
          <mass>3.176</mass>
          <inertia>
            <ixx>0.051911</ixx>
            <ixy>-1.27e-17</ixy>
            <ixz>-2.5162e-18</ixz>
            <iyy>0.059783</iyy>
            <iyz>4.8099e-18</iyz>
            <izz>0.051911</izz>
          </inertia>
        </inertial>
        <collision name='caja_link_collision'>
          <pose>0 0 0 0 -0 0</pose>
          <geometry>
            <mesh>
              <scale>1 1 1</scale>
              <uri>model://brazo/meshes/caja_link.STL</uri>
            </mesh>
          </geometry>
          <max_contacts>10</max_contacts>
          <surface>
            <contact>
              <ode/>
            </contact>
            <bounce/>
            <friction>
              <torsional>
                <ode/>
              </torsional>
              <ode/>
            </friction>
          </surface>
        </collision>
        <visual name='caja_link_visual'>
          <pose>0 0 0 0 -0 0</pose>
          <geometry>
            <mesh>
              <scale>1 1 1</scale>
              <uri>model://brazo/meshes/caja_link.STL</uri>
            </mesh>
          </geometry>
        </visual>
        <self_collide>0</self_collide>
        <enable_wind>0</enable_wind>
        <kinematic>0</kinematic>
      </link>
      <pose>0.5 -0.3 0.75 0 -0 0</pose>
    </model>
    <model name='box3'>
      <link name='caja_link'>
        <inertial>
          <pose>0 0.10733 -0 0 -0 0</pose>
          <mass>3.176</mass>
          <inertia>
            <ixx>0.051911</ixx>
            <ixy>-1.27e-17</ixy>
            <ixz>-2.5162e-18</ixz>
            <iyy>0.059783</iyy>
            <iyz>4.8099e-18</iyz>
            <izz>0.051911</izz>
          </inertia>
        </inertial>
        <collision name='caja_link_collision'>
          <pose>0 0 0 0 -0 0</pose>
          <geometry>
            <mesh>
              <scale>1 1 1</scale>
              <uri>model://brazo/meshes/caja_link.STL</uri>
            </mesh>
          </geometry>
          <max_contacts>10</max_contacts>
          <surface>
            <contact>
              <ode/>
            </contact>
            <bounce/>
            <friction>
              <torsional>
                <ode/>
              </torsional>
              <ode/>
            </friction>
          </surface>
        </collision>
        <visual name='caja_link_visual'>
          <pose>0 0 0 0 -0 0</pose>
          <geometry>
            <mesh>
              <scale>1 1 1</scale>
              <uri>model://brazo/meshes/caja_link.STL</uri>
            </mesh>
          </geometry>
        </visual>
        <self_collide>0</self_collide>
        <enable_wind>0</enable_wind>
        <kinematic>0</kinematic>
      </link>
      <pose>0.5 -0.3 0.75 0 -0 0</pose>
    </model>
    <model name='box4'>
      <link name='caja_link'>
        <inertial>
          <pose>0 0.10733 -0 0 -0 0</pose>
          <mass>3.176</mass>
          <inertia>
            <ixx>0.051911</ixx>
            <ixy>-1.27e-17</ixy>
            <ixz>-2.5162e-18</ixz>
            <iyy>0.059783</iyy>
            <iyz>4.8099e-18</iyz>
            <izz>0.051911</izz>
          </inertia>
        </inertial>
        <collision name='caja_link_collision'>
          <pose>0 0 0 0 -0 0</pose>
          <geometry>
            <mesh>
              <scale>1 1 1</scale>
              <uri>model://brazo/meshes/caja_link.STL</uri>
            </mesh>
          </geometry>
          <max_contacts>10</max_contacts>
          <surface>
            <contact>
              <ode/>
            </contact>
            <bounce/>
            <friction>
              <torsional>
                <ode/>
              </torsional>
              <ode/>
            </friction>
          </surface>
        </collision>
        <visual name='caja_link_visual'>
          <pose>0 0 0 0 -0 0</pose>
          <geometry>
            <mesh>
              <scale>1 1 1</scale>
              <uri>model://brazo/meshes/caja_link.STL</uri>
            </mesh>
          </geometry>
        </visual>
        <self_collide>0</self_collide>
        <enable_wind>0</enable_wind>
        <kinematic>0</kinematic>
      </link>
      <pose>0.5 -0.3 0.75 0 -0 0</pose>
    </model>
    <model name='box5'>
      <link name='caja_link'>
        <inertial>
          <pose>0 0.10733 -0 0 -0 0</pose>
          <mass>3.176</mass>
          <inertia>
            <ixx>0.051911</ixx>
            <ixy>-1.27e-17</ixy>
            <ixz>-2.5162e-18</ixz>
            <iyy>0.059783</iyy>
            <iyz>4.8099e-18</iyz>
            <izz>0.051911</izz>
          </inertia>
        </inertial>
        <collision name='caja_link_collision'>
          <pose>0 0 0 0 -0 0</pose>
          <geometry>
            <mesh>
              <scale>1 1 1</scale>
              <uri>model://brazo/meshes/caja_link.STL</uri>
            </mesh>
          </geometry>
          <max_contacts>10</max_contacts>
          <surface>
            <contact>
              <ode/>
            </contact>
            <bounce/>
            <friction>
              <torsional>
                <ode/>
              </torsional>
              <ode/>
            </friction>
          </surface>
        </collision>
        <visual name='caja_link_visual'>
          <pose>0 0 0 0 -0 0</pose>
          <geometry>
            <mesh>
              <scale>1 1 1</scale>
              <uri>model://brazo/meshes/caja_link.STL</uri>
            </mesh>
          </geometry>
        </visual>
        <self_collide>0</self_collide>
        <enable_wind>0</enable_wind>
        <kinematic>0</kinematic>
      </link>
      <pose>0.5 -0.3 0.75 0 -0 0</pose>
    </model>
  </world>
</sdf>
